#VRML_SIM R2023b utf8

EXTERNPROTO "https://raw.githubusercontent.com/cyberbotics/webots/R2023b/projects/objects/backgrounds/protos/TexturedBackground.proto"
EXTERNPROTO "https://raw.githubusercontent.com/cyberbotics/webots/R2023b/projects/objects/backgrounds/protos/TexturedBackgroundLight.proto"
EXTERNPROTO "https://raw.githubusercontent.com/cyberbotics/webots/R2023b/projects/objects/floors/protos/RectangleArena.proto"

WorldInfo {
}
Viewpoint {
  orientation 0.08901978018115199 0.3394243101063537 -0.936411563600816 0.5461276755786688
  position -7.676389716237336 3.7244373224656604 2.348987510272387
}
TexturedBackground {
}
TexturedBackgroundLight {
}
RectangleArena {
  floorSize 5 5
  floorTileSize 2 2
  wallHeight 0.25
}
DEF Ramp Solid {
  translation 0.725789 0.02 0.655337
  rotation 0 1 0 -0.261795307179586
  children [
    Shape {
      appearance PBRAppearance {
        baseColor 0.666667 0.537255 0.0196078
        roughness 1
        metalness 0
      }
      geometry Box {
        size 5 1 0.02
      }
    }
  ]
}
Robot {
  translation 2.53 0.0599997 1.45
  rotation 1 0 0 1.5708
  children [
    DEF smile Transform {
      translation -0.159994 -0.0750975 6.23703e-06
      rotation -0.25056300542381216 -0.9351130202419243 -0.25056300542381216 1.63784
      children [
        Shape {
          appearance PBRAppearance {
            baseColor 1 1 0
            roughness 1
            metalness 0
          }
          geometry Cylinder {
            height 0.2
            radius 0.08
          }
        }
      ]
    }
    HingeJoint {
      endPoint Solid {
        children [
          DistanceSensor {
            translation -0.26 0.07 -0.15
            rotation 0 1 0 -1.5707953071795862
            children [
              DEF right_eye Transform {
                children [
                  DEF right_eye Shape {
                    appearance PBRAppearance {
                      baseColor 0.666667 0.333333 1
                    }
                    geometry Cylinder {
                      height 0.01
                      radius 0.07
                    }
                  }
                ]
              }
              DEF left_eye Transform {
                translation 0.3 0 0
                children [
                  DEF left_eye Shape {
                    appearance PBRAppearance {
                      baseColor 0.666667 0.333333 1
                    }
                    geometry Cylinder {
                      height 0.01
                      radius 0.07
                    }
                  }
                ]
              }
            ]
          }
        ]
        name "solid(2)"
      }
    }
    DEF right_wheel HingeJoint {
      jointParameters HingeJointParameters {
      }
      device [
        DEF right_position_sensor PositionSensor {
        }
        DEF right_rotational_motor RotationalMotor {
        }
      ]
      endPoint Solid {
        translation 0 0 -0.35
        children [
          Shape {
            appearance PBRAppearance {
              baseColor 1 0.192157 0.65098
              roughness 0.7
              metalness 0.3
            }
            geometry Cylinder {
              height 0.1
              radius 0.275
            }
          }
        ]
      }
    }
    DEF left_wheel HingeJoint {
      jointParameters HingeJointParameters {
      }
      device [
        DEF leftt_position_sensor PositionSensor {
        }
        DEF left_rotational_motor RotationalMotor {
        }
      ]
      endPoint Solid {
        translation 0 0 0.33
        children [
          Shape {
            appearance PBRAppearance {
              baseColor 1 0.192157 0.65098
              roughness 0.7
              metalness 0.3
            }
            geometry Cylinder {
              height 0.1
              radius 0.275
            }
          }
        ]
        name "solid(1)"
      }
    }
    Accelerometer {
    }
    DistanceSensor {
    }
    DEF body Transform {
      children [
        Shape {
          appearance PBRAppearance {
            baseColor 0.333333 1 1
            roughness 0.5
            metalness 0.25
          }
          geometry Capsule {
            height 0.42
            radius 0.25
          }
        }
      ]
    }
  ]
}
